<?xml version="1.0" ?>
<!-- =================================================================================== -->
<!-- |    This document was autogenerated by xacro from lbr.urdf.xacro                 | -->
<!-- |    EDITING THIS FILE BY HAND IS NOT RECOMMENDED                                 | -->
<!-- =================================================================================== -->
<robot name="brics_lbr" xmlns:controller="http://playerstage.sourceforge.net/gazebo/xmlschema/#controller" xmlns:interface="http://playerstage.sourceforge.net/gazebo/xmlschema/#interface" xmlns:sensor="http://playerstage.sourceforge.net/gazebo/xmlschema/#sensor" xmlns:xacro="http://ros.org/wiki/xacro">
  <material name="Blue">
    <color rgba="0.0 0.0 0.8 1.0"/>
  </material>
  <material name="Green">
    <color rgba="0.0 0.8 0.0 1.0"/>
  </material>
  <material name="Grey">
    <color rgba="0.7 0.7 0.7 1.0"/>
  </material>
  <material name="Grey2">
    <color rgba="0.9 0.9 0.9 1.0"/>
  </material>
  <material name="Red">
    <color rgba="0.8 0.0 0.0 1.0"/>
  </material>
  <material name="White">
    <color rgba="1.0 1.0 1.0 1.0"/>
  </material>
  <material name="Black">
    <color rgba="0.0 0.0 0.0 1.0"/>
  </material>
  <material name="Caster">
    <texture filename="package://pr2_ogre/Media/materials/textures/pr2_caster_texture.png"/>
  </material>
  <material name="Wheel_l">
    <texture filename="package://pr2_ogre/Media/materials/textures/pr2_wheel_left.png"/>
  </material>
  <material name="Wheel_r">
    <texture filename="package://pr2_ogre/Media/materials/textures/pr2_wheel_right.png"/>
  </material>
  <material name="RollLinks">
    <texture filename="package://pr2_ogre/Media/materials/textures/pr2_wheel_left.png"/>
  </material>
  <gazebo>
    <controller:gazebo_ros_controller_manager name="gazebo_ros_controller_manager" plugin="libgazebo_ros_controller_manager.so">
      <alwaysOn>true</alwaysOn>
      <updateRate>1000.0</updateRate>
      <interface:audio name="gazebo_ros_controller_manager_dummy_iface"/>
    </controller:gazebo_ros_controller_manager>
    <controller:gazebo_ros_power_monitor name="gazebo_ros_power_monitor_controller" plugin="libgazebo_ros_power_monitor.so">
      <alwaysOn>true</alwaysOn>
      <updateRate>1.0</updateRate>
      <timeout>5</timeout>
      <interface:audio name="power_monitor_dummy_interface"/>
      <powerStateTopic>power_state</powerStateTopic>
      <powerStateRate>10.0</powerStateRate>
      <fullChargeCapacity>87.78</fullChargeCapacity>
      <dischargeRate>-474</dischargeRate>
      <chargeRate>525</chargeRate>
      <dischargeVoltage>15.52</dischargeVoltage>
      <chargeVoltage>16.41</chargeVoltage>
    </controller:gazebo_ros_power_monitor>
  </gazebo>
  <link name="base_link"/>
  <joint name="arm_0_joint" type="fixed">
    <origin rpy="0 0 0" xyz="0 0 0"/>
    <parent link="base_link"/>
    <child link="arm_0_link"/>
  </joint>
  <link name="arm_0_link">
    <inertial>
      <origin rpy="0 0 0" xyz="0 0 -0.07"/>
      <mass value="1.0"/>
      <inertia ixx="0.01" ixy="0" ixz="0" iyy="0.01" iyz="0" izz="0.01"/>
    </inertial>
    <visual>
      <origin rpy="0 0 0" xyz="0 0 -0.07"/>
      <geometry>
        <cylinder length="0.14" radius="0.060"/>
      </geometry>
      <material name="Red"/>
    </visual>
    <collision>
      <origin rpy="0 0 0" xyz="0 0 -0.07"/>
      <geometry>
        <box size="0.01 0.01 0.01"/>
      </geometry>
    </collision>
  </link>
  <joint name="arm_1_joint" type="revolute">
    <origin rpy="0 0 -2.8407" xyz="0 0 0.0"/>
    <parent link="arm_0_link"/>
    <child link="arm_1_link"/>
    <axis xyz="0 0 1"/>
    <calibration rising="0.0"/>
    <dynamics damping="10"/>
    <limit effort="200" lower="-2.9670" upper="2.9670" velocity="1.9634"/>
    <safety_controller k_position="20" k_velocity="50" soft_lower_limit="-2.957" soft_upper_limit="2.957"/>
  </joint>
  <link name="arm_1_link">
    <inertial>
      <origin rpy="0 0 0" xyz="0 0 0"/>
      <!--mass value="5.9907"/-->
      <mass value="2.0"/>
      <inertia ixx="0.01" ixy="0" ixz="0" iyy="0.01" iyz="0" izz="0.01"/>
    </inertial>
    <visual>
      <origin rpy="0 0 0" xyz="0 0 0"/>
      <geometry>
        <mesh filename="package://cob_description/meshes/lbr/joint_1.stl"/>
      </geometry>
      <material name="Blue"/>
    </visual>
    <collision>
      <origin rpy="0 0 0" xyz="0 0 0"/>
      <geometry>
        <mesh filename="package://cob_description/meshes/lbr/joint_1_collision.stl"/>
      </geometry>
    </collision>
  </link>
  <joint name="arm_2_joint" type="revolute">
    <origin rpy="1.57079632679 0 0" xyz="0 -0.002 0.1915"/>
    <parent link="arm_1_link"/>
    <child link="arm_2_link"/>
    <axis xyz="0 0 1"/>
    <calibration rising="0.0"/>
    <dynamics damping="10"/>
    <limit effort="200" lower="-2.0943" upper="2.0943" velocity="1.9634"/>
    <safety_controller k_position="20" k_velocity="50" soft_lower_limit="-2.0843" soft_upper_limit="2.0843"/>
  </joint>
  <link name="arm_2_link">
    <inertial>
      <origin rpy="0 0 0" xyz="0 0 0"/>
      <!--mass value="5.734939"/-->
      <mass value="2.0"/>
      <inertia ixx="0.03" ixy="0" ixz="0" iyy="0.03" iyz="0" izz="0.03"/>
    </inertial>
    <visual>
      <origin rpy="0 0 0" xyz="0 0 0"/>
      <geometry>
        <mesh filename="package://cob_description/meshes/lbr/joint_2.stl"/>
      </geometry>
      <material name="Red"/>
    </visual>
    <collision>
      <origin rpy="0 0 0" xyz="0 0 0"/>
      <geometry>
        <mesh filename="package://cob_description/meshes/lbr/joint_2_collision.stl"/>
      </geometry>
    </collision>
  </link>
  <joint name="arm_3_joint" type="revolute">
    <origin rpy="-1.57079632679 0 0" xyz="0 0.2085 0"/>
    <parent link="arm_2_link"/>
    <child link="arm_3_link"/>
    <axis xyz="0 0 1"/>
    <calibration rising="0.0"/>
    <dynamics damping="5"/>
    <limit effort="100" lower="-2.9670" upper="2.9670" velocity="1.9634"/>
    <safety_controller k_position="20" k_velocity="25" soft_lower_limit="-2.957" soft_upper_limit="2.957"/>
  </joint>
  <link name="arm_3_link">
    <inertial>
      <origin rpy="0 0 0" xyz="0 0 0"/>
      <!--mass value="4.214668"/-->
      <mass value="2.0"/>
      <inertia ixx="0.03" ixy="0" ixz="0" iyy="0.03" iyz="0" izz="0.03"/>
    </inertial>
    <visual>
      <origin rpy="0 0 0" xyz="0 0 0"/>
      <geometry>
        <mesh filename="package://cob_description/meshes/lbr/joint_3.stl"/>
      </geometry>
      <material name="Blue"/>
    </visual>
    <collision>
      <origin rpy="0 0 0" xyz="0 0 0"/>
      <geometry>
        <mesh filename="package://cob_description/meshes/lbr/joint_3_collision.stl"/>
      </geometry>
    </collision>
  </link>
  <joint name="arm_4_joint" type="revolute">
    <origin rpy="-1.57079632679 0 0" xyz="0 0.002 0.1915"/>
    <parent link="arm_3_link"/>
    <child link="arm_4_link"/>
    <axis xyz="0 0 1"/>
    <calibration rising="0.0"/>
    <dynamics damping="5"/>
    <limit effort="100" lower="-2.0943" upper="2.0943" velocity="1.9634"/>
    <!--limit effort="176" velocity="0.4189" upper="2.0943951" lower="-2.0943951"/-->
    <safety_controller k_position="20" k_velocity="25" soft_lower_limit="-2.0843" soft_upper_limit="2.0843"/>
  </joint>
  <link name="arm_4_link">
    <inertial>
      <origin rpy="0 0 0" xyz="0 0 0"/>
      <!--mass value="3.669819"/-->
      <mass value="2.0"/>
      <inertia ixx="0.03" ixy="0" ixz="0" iyy="0.03" iyz="0" izz="0.03"/>
    </inertial>
    <visual>
      <origin rpy="0 0 0" xyz="0 0 0"/>
      <geometry>
        <mesh filename="package://cob_description/meshes/lbr/joint_4.stl"/>
      </geometry>
      <material name="Red"/>
    </visual>
    <collision>
      <origin rpy="0 0 0" xyz="0 0 0"/>
      <geometry>
        <mesh filename="package://cob_description/meshes/lbr/joint_4_collision.stl"/>
      </geometry>
    </collision>
  </link>
  <joint name="arm_5_joint" type="revolute">
    <origin rpy="1.57079632679 0 0" xyz="0 -0.2085 0"/>
    <parent link="arm_4_link"/>
    <child link="arm_5_link"/>
    <axis xyz="0 0 1"/>
    <calibration rising="0.0"/>
    <dynamics damping="5"/>
    <limit effort="100" lower="-2.9670" upper="2.9670" velocity="1.9634"/>
    <safety_controller k_position="20" k_velocity="25" soft_lower_limit="-2.957" soft_upper_limit="2.957"/>
  </joint>
  <link name="arm_5_link">
    <inertial>
      <origin rpy="0 0 0" xyz="0 0 0"/>
      <mass value="2.313272"/>
      <inertia ixx="0.03" ixy="0" ixz="0" iyy="0.03" iyz="0" izz="0.03"/>
    </inertial>
    <visual>
      <origin rpy="0 0 0" xyz="0 0 0"/>
      <geometry>
        <mesh filename="package://cob_description/meshes/lbr/joint_5.stl"/>
      </geometry>
      <material name="Blue"/>
    </visual>
    <collision>
      <origin rpy="0 0 0" xyz="0 0 0"/>
      <geometry>
        <mesh filename="package://cob_description/meshes/lbr/joint_5_collision.stl"/>
      </geometry>
    </collision>
  </link>
  <joint name="arm_6_joint" type="revolute">
    <origin rpy="1.57079632679 0 0" xyz="0 0.046 0.1815"/>
    <parent link="arm_5_link"/>
    <child link="arm_6_link"/>
    <axis xyz="0 0 1"/>
    <calibration rising="0.0"/>
    <dynamics damping="5"/>
    <limit effort="30" lower="-2.0943951" upper="2.0943951" velocity="1.9634"/>
    <!--limit effort="20.1" velocity="0.4363" upper="2.0943951" lower="-2.0943951" /-->
    <safety_controller k_position="20" k_velocity="25" soft_lower_limit="-2.0843951" soft_upper_limit="2.0843951"/>
  </joint>
  <link name="arm_6_link">
    <inertial>
      <origin rpy="0 0 0" xyz="0 0 0"/>
      <mass value="2.057856"/>
      <inertia ixx="0.01" ixy="0" ixz="0" iyy="0.01" iyz="0" izz="0.01"/>
    </inertial>
    <visual>
      <origin rpy="0 0 0" xyz="0 0 0"/>
      <geometry>
        <mesh filename="package://cob_description/meshes/lbr/joint_6.stl"/>
      </geometry>
      <material name="Red"/>
    </visual>
    <collision>
      <origin rpy="0 0 0" xyz="0 0 0"/>
      <geometry>
        <mesh filename="package://cob_description/meshes/lbr/joint_6_collision.stl"/>
      </geometry>
    </collision>
  </link>
  <joint name="arm_7_joint" type="revolute">
    <origin rpy="-1.57079632679 0 0" xyz="0 0.057 0.0455"/>
    <parent link="arm_6_link"/>
    <child link="arm_7_link"/>
    <axis xyz="0 0 1"/>
    <calibration rising="0.0"/>
    <dynamics damping="5"/>
    <limit effort="30" lower="-2.9670" upper="2.9670" velocity="1.9634"/>
    <!--limit effort="20.1" velocity="0.4363" upper="2.0943951" lower="-2.0943951" /-->
    <safety_controller k_position="20" k_velocity="25" soft_lower_limit="-2.957" soft_upper_limit="2.957"/>
  </joint>
  <link name="arm_7_link">
    <inertial>
      <origin rpy="0 0 0" xyz="0 0 0"/>
      <mass value="1.120198"/>
      <inertia ixx="0.01" ixy="0" ixz="0" iyy="0.01" iyz="0" izz="0.01"/>
    </inertial>
    <visual>
      <origin rpy="0 0 0" xyz="0 0 0"/>
      <geometry>
        <mesh filename="package://cob_description/meshes/lbr/joint_7.stl"/>
      </geometry>
      <material name="Blue"/>
    </visual>
    <collision>
      <origin rpy="0 0 0" xyz="0 0 0"/>
      <geometry>
        <mesh filename="package://cob_description/meshes/lbr/joint_7_collision.stl"/>
      </geometry>
    </collision>
  </link>
  <gazebo reference="arm_0_link">
    <material value="PR2/Red"/>
    <turnGravityOff>false</turnGravityOff>
  </gazebo>
  <gazebo reference="arm_1_link">
    <material value="PR2/Blue"/>
    <turnGravityOff>false</turnGravityOff>
  </gazebo>
  <gazebo reference="arm_2_link">
    <material value="PR2/Red"/>
    <turnGravityOff>false</turnGravityOff>
  </gazebo>
  <gazebo reference="arm_3_link">
    <material value="PR2/Blue"/>
    <turnGravityOff>false</turnGravityOff>
  </gazebo>
  <gazebo reference="arm_4_link">
    <material value="PR2/Red"/>
    <turnGravityOff>false</turnGravityOff>
  </gazebo>
  <gazebo reference="arm_5_link">
    <material value="PR2/Blue"/>
    <turnGravityOff>false</turnGravityOff>
  </gazebo>
  <gazebo reference="arm_6_link">
    <material value="PR2/Red"/>
    <turnGravityOff>false</turnGravityOff>
  </gazebo>
  <gazebo reference="arm_7_link">
    <material value="PR2/Blue"/>
    <turnGravityOff>false</turnGravityOff>
  </gazebo>
  <transmission name="arm_1_trans" type="pr2_mechanism_model/SimpleTransmission">
    <actuator name="arm_1_motor"/>
    <joint name="arm_1_joint"/>
    <mechanicalReduction>1</mechanicalReduction>
  </transmission>
  <transmission name="arm_2_trans" type="pr2_mechanism_model/SimpleTransmission">
    <actuator name="arm_2_motor"/>
    <joint name="arm_2_joint"/>
    <mechanicalReduction>1</mechanicalReduction>
  </transmission>
  <transmission name="arm_3_trans" type="pr2_mechanism_model/SimpleTransmission">
    <actuator name="arm_3_motor"/>
    <joint name="arm_3_joint"/>
    <mechanicalReduction>1</mechanicalReduction>
  </transmission>
  <transmission name="arm_4_trans" type="pr2_mechanism_model/SimpleTransmission">
    <actuator name="arm_4_motor"/>
    <joint name="arm_4_joint"/>
    <mechanicalReduction>1</mechanicalReduction>
  </transmission>
  <transmission name="arm_5_trans" type="pr2_mechanism_model/SimpleTransmission">
    <actuator name="arm_5_motor"/>
    <joint name="arm_5_joint"/>
    <mechanicalReduction>1</mechanicalReduction>
  </transmission>
  <transmission name="arm_6_trans" type="pr2_mechanism_model/SimpleTransmission">
    <actuator name="arm_6_motor"/>
    <joint name="arm_6_joint"/>
    <mechanicalReduction>1</mechanicalReduction>
  </transmission>
  <transmission name="arm_7_trans" type="pr2_mechanism_model/SimpleTransmission">
    <actuator name="arm_7_motor"/>
    <joint name="arm_7_joint"/>
    <mechanicalReduction>1</mechanicalReduction>
  </transmission>
</robot>

